WARNING querier.rollback Starting rollback from 125879291.208e6c0e7a0555e981cd33694a7502d65983dd94775346ffb4fcc293ba9cfa75
WARNING querier.rollback Rolled back 9 blocks, now at 125879282.a783eb661f85f67fb11a5e003bd720a85ab02091a6137bc0ed883ce35eb2c3c6
WARNING querier.rollback Executing rollback to block 125879282.a783eb661f85f67fb11a5e003bd720a85ab02091a6137bc0ed883ce35eb2c3c6
WARNING querier.rollback Starting rollback from 125879291.208e6c0e7a0555e981cd33694a7502d65983dd94775346ffb4fcc293ba9cfa75
WARNING querier.rollback Rolled back 9 blocks, now at 125879282.a783eb661f85f67fb11a5e003bd720a85ab02091a6137bc0ed883ce35eb2c3c6
WARNING querier.rollback Executing rollback to block 125879282.a783eb661f85f67fb11a5e003bd720a85ab02091a6137bc0ed883ce35eb2c3c6
WARNING querier.rollback Starting rollback from 125879291.208e6c0e7a0555e981cd33694a7502d65983dd94775346ffb4fcc293ba9cfa75
WARNING querier.rollback Rolled back 9 blocks, now at 125879282.a783eb661f85f67fb11a5e003bd720a85ab02091a6137bc0ed883ce35eb2c3c6
WARNING querier.rollback Executing rollback to block 125879282.a783eb661f85f67fb11a5e003bd720a85ab02091a6137bc0ed883ce35eb2c3c6
ERROR __main__ Exception in Ogmios thread
Traceback (most recent call last):
  File "/home/padowd/openswap/muesliswap-batcher-analytics/venv/lib/python3.12/site-packages/websockets/sync/connection.py", line 683, in send_context
    self.send_data()
  File "/home/padowd/openswap/muesliswap-batcher-analytics/venv/lib/python3.12/site-packages/websockets/sync/connection.py", line 745, in send_data
    self.socket.sendall(data)
BrokenPipeError: [Errno 32] Broken pipe

The above exception was the direct cause of the following exception:

Traceback (most recent call last):
  File "/home/padowd/openswap/muesliswap-batcher-analytics/querier/__main__.py", line 101, in _run_ogmios_async
    for block in block_generator:
  File "/home/padowd/openswap/muesliswap-batcher-analytics/querier/ogmios.py", line 44, in iterate_blocks
    client.next_block.send()
  File "/home/padowd/openswap/muesliswap-batcher-analytics/venv/lib/python3.12/site-packages/ogmios/chainsync/NextBlock.py", line 60, in send
    self.client.send(pld.json())
  File "/home/padowd/openswap/muesliswap-batcher-analytics/venv/lib/python3.12/site-packages/ogmios/client.py", line 125, in send
    self.connection.send(request)
  File "/home/padowd/openswap/muesliswap-batcher-analytics/venv/lib/python3.12/site-packages/websockets/sync/connection.py", line 288, in send
    with self.send_context():
  File "/home/padowd/miniconda3/lib/python3.12/contextlib.py", line 144, in __exit__
    next(self.gen)
  File "/home/padowd/openswap/muesliswap-batcher-analytics/venv/lib/python3.12/site-packages/websockets/sync/connection.py", line 728, in send_context
    raise self.protocol.close_exc from original_exc
websockets.exceptions.ConnectionClosedError: no close frame received or sent
WARNING querier.rollback Starting rollback from 125879291.208e6c0e7a0555e981cd33694a7502d65983dd94775346ffb4fcc293ba9cfa75
WARNING querier.rollback Rolled back 9 blocks, now at 125879282.a783eb661f85f67fb11a5e003bd720a85ab02091a6137bc0ed883ce35eb2c3c6
WARNING querier.rollback Executing rollback to block 125879282.a783eb661f85f67fb11a5e003bd720a85ab02091a6137bc0ed883ce35eb2c3c6
